<?xml version="1.0"?>

<robot name="Block">

    <link name="world">
    </link>

    <link name="body">
        <inertial>
            <origin xyz="0 0 0" rpy="0 0 0" />
            <mass value="10" />
            <inertia ixx="41.6667" ixy="0" ixz="0" iyy="104.1667" iyz="0" izz="104.1667" />
        </inertial>
        <visual>
            <origin xyz="0 0 0" rpy="0 0 0" />
            <geometry>
                <box size="10 5 5" />
            </geometry>
            <material name="green">
	            <color rgba="0.1 0.5 0.05 0.5" />
            </material>
        </visual>
    </link>

    <joint name="body_to_world" type="floating">
        <parent link="world" />
        <child link="body" />
    </joint>

</robot>
